Workbook

Sheet RTM
A1: Req ID | B1: Module # | C1: Module | D1: Title | E1: Priority | F1: Functional Requirement | G1: Sub-reqs | H1: Interfaces | I1: Prototype status | J1: Gap / notes | K1: Shared services | L1: Release | M1: Planned sprints | N1: Size | O1: Story points | P1: Decision refs | Q1: Test cases | R1: SME / UAT owner | S1: Delivery status
A2: REG-REQ01 | B2: 1 | C2: User Registration & Account Management | D2: Tax Club Member Registration | E2: High | F2: The system shall allow an eligible user to register for a TRA Tax Club account through the Mobile Application or Web Application by providing the mandatory personal, contact, membership and institutional information. | G2: 9 | H2: Mobile / Web / Admin | I2: Partial | J2: API register exists (name, email, phone, password, user_type, institution). Missing: DOB/age band, gender, region, consent/guardian, registration reference, Pending Verification status (currently auto-verified + token issued), inactive-institution check, member-facing registration UI in repo. UPDATE 16-Oct-2026: Web + API registration with Pending Verification and reference number (branch feat/laravel13-livewire-tailwind). Still missing: DOB/age band, guardian consent capture, region, confirmation notification. | K2: Workflow, Audience, Notifications, Cases/Numbering, Safeguarding, Scoped RBAC | L2: R1 | M2: S2–S6 | N2: L | O2: 6 | P2: D-04, D-06, D-07 | Q2: TC-REG-REQ01-01..09 | R2: TRA Taxpayer Education / Tax Club Programme Responsible Officer | S2: Done
A3: REG-REQ02 | B3: 1 | C3: User Registration & Account Management | D3: Tax Club Membership Verification | E3: High | F3: The system shall allow an authorized user to verify, approve or reject a submitted Tax Club membership registration. | G3: 9 | H3: Mobile / Web / Admin | I3: Not started | J3: No implementation in prototype. UPDATE 16-Oct-2026: Verification queue with filters, approve/reject with reason, officer and time recorded. Still missing: coordinator/patron scope, applicant notification. UPDATE 17-Oct-2026: Verification queue now scoped: patrons see and decide only their own institution; TRA officers need view_all_registrations. Still missing: region-scoped coordinators, applicant notification. | K3: Workflow, Notifications, Audit, Cases/Numbering, Scoped RBAC | L3: R1 | M3: S2–S6 | N3: M | O3: 5 | P3: D-05, D-09 | Q3: TC-REG-REQ02-01..09 | R3: TRA Tax Club Programme Coordinator / Responsible Taxpayer Education Officer | S3: Done
A4: REG-REQ03 | B4: 1 | C4: User Registration & Account Management | D4: Account Activation | E4: High | F4: The system shall activate a Tax Club member account after successful membership verification and allow the verified member to access services permitted for their assigned membership category. | G4: 8 | H4: Mobile / Web | I4: Not started | J4: No implementation in prototype. UPDATE 16-Oct-2026: Approval activates the account and issues an interim membership number. Still missing: notification, final number format (D-03). | K4: Workflow, Audience, Notifications, Audit, Cases/Numbering | L4: R1 | M4: S2–S6 | N4: M | O4: 5 | Q4: TC-REG-REQ03-01..08 | R4: TRA Tax Club Programme Coordinator / Responsible Taxpayer Education Officer | S4: Done
A5: REG-REQ04 | B5: 1 | C5: User Registration & Account Management | D5: User Login | E5: High | F5: The system shall allow a registered and active user to securely log in to the TRA Tax Club Digital Platform through the Mobile Application or Web Application using approved authentication credentials. | G5: 9 | H5: Mobile / Web | I5: Partial | J5: Email+password login with Sanctum token and permission list; single-session. Missing: phone login, lockout/rate limit, login audit, token expiry, suspended-status enforcement, MFA for staff. UPDATE 16-Oct-2026: Web sign-in by phone or email with rate limiting and status checks; API login blocks non-active accounts. Still missing: login audit, token expiry, staff MFA. | K5: Workflow, Audit | L5: R1 | M5: S2–S6 | N5: L | O5: 6 | P5: D-07, D-08 | Q5: TC-REG-REQ04-01..09 | R5: TRA ICT Security / Tax Club Programme Responsible Officer | S5: In progress
A6: REG-REQ05 | B6: 1 | C6: User Registration & Account Management | D6: Account Recovery and Credential Reset | E6: High | F6: The system shall allow a registered user who cannot access their account to securely recover the account or reset their authentication credentials through an approved identity-verification mechanism. | G6: 10 | H6: Admin | I6: Not started | J6: No implementation in prototype. | K6: Workflow, Notifications, Audit, Cases/Numbering | L6: R1 | M6: S2–S6 | N6: L | O6: 8 | P6: D-07 | Q6: TC-REG-REQ05-01..10 | R6: TRA ICT Security / System Administration Team | S6: Done
A7: REG-REQ06 | B7: 1 | C7: User Registration & Account Management | D7: Account Suspension, Deactivation and Reactivation | E7: High | F7: The system shall allow an authorized user to suspend, deactivate or reactivate a Tax Club user account in accordance with approved membership, moderation, security and administrative rules. | G7: 10 | H7: Mobile / Web / Admin | I7: Not started | J7: No implementation in prototype. | K7: Workflow, Audience, Notifications, Audit, Safeguarding | L7: R1 | M7: S2–S6 | N7: M | O7: 5 | Q7: TC-REG-REQ06-01..10 | R7: TRA Tax Club Programme Coordinator / Moderator / ICT Security Representative | S7: Planned
A8: REG-REQ07 | B8: 1 | C8: User Registration & Account Management | D8: Transition of Student Member to Alumni | E8: High | F8: The system shall allow an eligible Tax Club member to transition from active student membership to Tax Club Alumni status while retaining approved membership history, learning achievements and participation records. | G8: 10 | H8: Mobile / Web / Admin | I8: Not started | J8: No implementation in prototype. | K8: Workflow, Audience, Notifications, Audit, Cases/Numbering | L8: R1 | M8: S2–S6 | N8: L | O8: 8 | P8: D-12 | Q8: TC-REG-REQ07-01..10 | R8: TRA Tax Club Programme Coordinator / Responsible Taxpayer Education Officer | S8: Planned
A9: PRO-REQ01 | B9: 2 | C9: Member Profile & Digital Membership | D9: View Member Profile | E9: High | F9: The system shall allow a registered Tax Club member to view their profile information through the Mobile Application or Web Application. | G9: 8 | H9: Mobile / Web | I9: Partial | J9: GET /auth/me returns basic profile and institution. Missing: membership status/category display rules, achievements, badges, certificates. | K9: Workflow, Scoped RBAC | L9: R1 | M9: S2–S6 | N9: S | O9: 2 | Q9: TC-PRO-REQ01-01..08 | R9: TRA Tax Club Programme Coordinator / Responsible Taxpayer Education Officer | S9: Planned
A10: PRO-REQ02 | B10: 2 | C10: Member Profile & Digital Membership | D10: Update Member Profile | E10: High | F10: The system shall allow a Tax Club member to update permitted personal and profile information through the Mobile Application or Web Application. | G10: 8 | H10: Mobile / Web | I10: Not started | J10: No implementation in prototype. | K10: Workflow, Notifications, Audit, Safeguarding | L10: R1 | M10: S2–S6 | N10: M | O10: 5 | Q10: TC-PRO-REQ02-01..08 | R10: TRA Tax Club Programme Coordinator / System Administrator | S10: Planned
A11: PRO-REQ03 | B11: 2 | C11: Member Profile & Digital Membership | D11: Member Profile Privacy Management | E11: High | F11: The system shall control the visibility of member profile information based on user role, membership category, privacy rules and approved safeguarding requirements. | G11: 7 | H11: Mobile / Web / Admin | I11: Not started | J11: No implementation in prototype. | K11: Workflow, Cases/Numbering, Safeguarding | L11: R1 | M11: S2–S6 | N11: L | O11: 8 | P11: D-04 | Q11: TC-PRO-REQ03-01..07 | R11: TRA ICT Security / Tax Club Programme Coordinator / Data Protection Responsible Officer | S11: Planned
A12: MEM-REQ01 | B12: 2 | C12: Member Profile & Digital Membership | D12: Generate Digital Tax Club Membership Number | E12: High | F12: The system shall generate a unique Tax Club membership number for each successfully verified and activated Tax Club member. | G12: 7 | H12: Mobile / Web / Admin | I12: Partial | J12: Random TRA-XXXXXXXX assigned at registration. Must be issued only on activation, in approved format, sequence-based, retained for alumni. | K12: Workflow, Audit | L12: R1 | M12: S2–S6 | N12: S | O12: 2 | P12: D-03 | Q12: TC-MEM-REQ01-01..07 | R12: TRA Tax Club Programme Coordinator / System Administrator | S12: Done
A13: MEM-REQ02 | B13: 2 | C13: Member Profile & Digital Membership | D13: Digital Tax Club Membership Card | E13: High | F13: The system shall generate and display a digital Tax Club membership card for each verified and active Tax Club member through the Mobile Application and Web Application. | G13: 9 | H13: Mobile / Web | I13: Not started | J13: No implementation in prototype. | K13: Workflow | L13: R1 | M13: S2–S6 | N13: L | O13: 8 | P13: D-03 | Q13: TC-MEM-REQ02-01..09 | R13: TRA Tax Club Programme Coordinator / Responsible Taxpayer Education Officer | S13: Done
A14: MEM-REQ03 | B14: 2 | C14: Member Profile & Digital Membership | D14: Digital Membership Verification | E14: High | F14: The system shall allow an authorized user to verify the validity and current status of a Tax Club member's digital membership using the membership number, QR code or other approved verification mechanism. | G14: 7 | H14: Mobile / Web / Admin | I14: Not started | J14: No implementation in prototype. | K14: Workflow, Audience | L14: R1 | M14: S2–S6 | N14: M | O14: 5 | P14: D-13 | Q14: TC-MEM-REQ03-01..07 | R14: TRA Tax Club Programme Coordinator / Tax Club Patron | S14: Done
A15: MEM-REQ04 | B15: 2 | C15: Member Profile & Digital Membership | D15: Membership Status Management | E15: High | F15: The system shall maintain and display the current Tax Club membership status of each member throughout the membership lifecycle. | G15: 8 | H15: Mobile / Web / Admin | I15: Not started | J15: No implementation in prototype. | K15: Workflow, Notifications, Audit | L15: R1 | M15: S2–S6 | N15: M | O15: 5 | Q15: TC-MEM-REQ04-01..08 | R15: TRA Tax Club Programme Coordinator / System Administrator | S15: In progress
A16: INS-REQ01 | B16: 3 | C16: Institution & Tax Club Management | D16: Institution Registration | E16: High | F16: The system shall allow an authorized user to register an educational institution participating in the TRA Tax Club programme through the Administration Portal. | G16: 10 | H16: Mobile / Web / Admin | I16: Partial | J16: Create institution with name, type, region, district. Missing: unique code, contacts, has_tax_club, status, duplicate check, created_by, region/district master data. UPDATE 17-Oct-2026: Admin form + CSV import: category, 31-region list, district, contacts, generated code (e.g. DSM-S-0042), duplicate check, created_by, active on creation. | K16: Workflow, Audit, Cases/Numbering, Scoped RBAC | L16: R1 | M16: S2–S6 | N16: M | O16: 4 | Q16: TC-INS-REQ01-01..10 | R16: TRA Tax Club Programme Coordinator / Responsible Taxpayer Education Officer | S16: Done
A17: INS-REQ02 | B17: 3 | C17: Institution & Tax Club Management | D17: Update Institution Information | E17: High | F17: The system shall allow an authorized user to update approved information relating to a registered educational institution. | G17: 8 | H17: Mobile / Web / Admin | I17: Partial | J17: Update endpoint exists. Missing: audit history (before/after), identifier protection. UPDATE 17-Oct-2026: Edit form with code protected and duplicate check. Still missing: before/after audit log of field changes (shared Audit service). | K17: Workflow, Audit, Scoped RBAC | L17: R1 | M17: S2–S6 | N17: S | O17: 2 | Q17: TC-INS-REQ02-01..08 | R17: TRA Tax Club Programme Coordinator / System Administrator | S17: In progress
A18: INS-REQ03 | B18: 3 | C18: Institution & Tax Club Management | D18: Institution Activation and Deactivation | E18: High | F18: The system shall allow an authorized user to activate or deactivate a registered institution for participation in the TRA Tax Club Digital Platform. | G18: 9 | H18: Mobile / Web / Admin | I18: Not started | J18: No implementation in prototype. UPDATE 17-Oct-2026: Activate/deactivate with mandatory reason and status history; inactive institutions hidden from registration and the public API; members kept. | K18: Workflow, Audit, Cases/Numbering | L18: R1 | M18: S2–S6 | N18: S | O18: 3 | Q18: TC-INS-REQ03-01..09 | R18: TRA Tax Club Programme Coordinator / Responsible Taxpayer Education Officer | S18: Done
A19: INS-REQ04 | B19: 3 | C19: Institution & Tax Club Management | D19: Tax Club Establishment and Management | E19: High | F19: The system shall allow an authorized user to establish and manage a Tax Club under a registered educational institution. | G19: 9 | H19: Mobile / Web / Admin | I19: Not started | J19: No implementation in prototype. UPDATE 17-Oct-2026: Tax Club per institution, establishment date, status with reason, one active club per institution. | K19: Workflow, Audience, Audit, Cases/Numbering, Scoped RBAC | L19: R1 | M19: S2–S6 | N19: M | O19: 5 | Q19: TC-INS-REQ04-01..09 | R19: TRA Tax Club Programme Coordinator / Responsible Taxpayer Education Officer | S19: Done
A20: INS-REQ05 | B20: 3 | C20: Institution & Tax Club Management | D20: Tax Club Patron Assignment | E20: High | F20: The system shall allow an authorized user to assign, replace or remove a Tax Club Patron responsible for coordinating Tax Club activities within a registered educational institution. | G20: 9 | H20: Admin | I20: Not started | J20: No implementation in prototype. UPDATE 17-Oct-2026: Assign patron by phone (existing user or new staff account with one-time password), start date, end with reason, history kept, Patron role granted/removed. Still missing: notification to the patron (Notifications module). | K20: Workflow, Notifications, Audit, Cases/Numbering | L20: R1 | M20: S2–S6 | N20: M | O20: 5 | Q20: TC-INS-REQ05-01..09 | R20: TRA Tax Club Programme Coordinator / Participating Educational Institution Representative | S20: In progress
A21: INS-REQ06 | B21: 3 | C21: Institution & Tax Club Management | D21: TRA Tax Club Coordinator Assignment | E21: High | F21: The system shall allow an authorized user to assign TRA Tax Club Coordinators to institutions, Tax Clubs, regions or other approved programme areas. | G21: 8 | H21: Admin | I21: Not started | J21: No implementation in prototype. | K21: Workflow, Audit, Cases/Numbering, Scoped RBAC | L21: R1 | M21: S2–S6 | N21: L | O21: 8 | P21: D-09 | Q21: TC-INS-REQ06-01..08 | R21: TRA Taxpayer Education Management / Tax Club Programme Coordinator | S21: Planned
A22: INS-REQ07 | B22: 3 | C22: Institution & Tax Club Management | D22: Search and View Institutions and Tax Clubs | E22: Medium | F22: The system shall allow authorized users to search, filter and view registered institutions and their associated Tax Clubs according to the user's access rights. | G22: 10 | H22: Mobile / Web / Admin | I22: Partial | J22: List supports search by name and filter by type/region. Missing: district/status/club filters, patron/coordinator display, stats, scope-restricted results. UPDATE 17-Oct-2026: Search by name/code/district; filters by category, region, status; shows Tax Club and patrons. Still missing: coordinator display and region-scoped results (INS-REQ06). | K22: Workflow, Scoped RBAC | L22: R1 | M22: S2–S6 | N22: M | O22: 4 | Q22: TC-INS-REQ07-01..10 | R22: TRA Tax Club Programme Coordinator / Tax Education Management | S22: In progress
A23: INS-REQ08 | B23: 3 | C23: Institution & Tax Club Management | D23: Institution and Tax Club Membership Statistics | E23: Medium | F23: The system shall calculate and display approved membership statistics for each registered institution and Tax Club. | G23: 8 | H23: Mobile / Web / Admin | I23: Not started | J23: No implementation in prototype. UPDATE 17-Oct-2026: Per-institution active, waiting and alumni counts (staff excluded). Still missing: category breakdown and dashboard/report export. | K23: Workflow, Scoped RBAC | L23: R1 | M23: S2–S6 | N23: M | O23: 5 | Q23: TC-INS-REQ08-01..08 | R23: TRA Tax Club Programme Coordinator / Monitoring and Evaluation Responsible Officer | S23: In progress
A24: LRN-REQ01 | B24: 4 | C24: Learning & Content Management | D24: Create Learning Content | E24: High | F24: The system shall allow an authorized content officer to create and save Tax Club learning content through the Administration Portal. | G24: 9 | H24: Mobile / Web / Admin | I24: Partial | J24: Admin create with title, type (video/article/infographic/quiz), file_url, rich-text body. Missing: categories, summary/objectives, uploads with validation, Draft status, content code, more content types. | K24: Workflow, Audience, Audit, Cases/Numbering | L24: R2 | M24: S7–S9 | N24: L | O24: 6 | Q24: TC-LRN-REQ01-01..09 | R24: TRA Taxpayer Education / Content Management Responsible Officer | S24: Planned
A25: LRN-REQ02 | B25: 4 | C25: Learning & Content Management | D25: Review and Approve Learning Content | E25: High | F25: The system shall allow an authorized reviewer or approver to review, approve, reject or return submitted learning content for correction before publication. | G25: 9 | H25: Admin | I25: Not started | J25: No implementation in prototype. | K25: Workflow, Audience, Notifications, Audit | L25: R2 | M25: S7–S9 | N25: M | O25: 5 | Q25: TC-LRN-REQ02-01..09 | R25: TRA Taxpayer Education Content Reviewer / Relevant TRA Subject Matter Expert | S25: Planned
A26: LRN-REQ03 | B26: 4 | C26: Learning & Content Management | D26: Publish, Schedule, Unpublish and Archive Learning Content | E26: High | F26: The system shall allow an authorized user to publish, schedule, unpublish or archive approved learning content through the Administration Portal. | G26: 9 | H26: Mobile / Web / Admin | I26: Partial | J26: is_active toggle and published_at only. Missing: approved-only publishing, scheduling, expiry, archive, history. | K26: Workflow, Audience, Audit | L26: R2 | M26: S7–S9 | N26: M | O26: 4 | Q26: TC-LRN-REQ03-01..09 | R26: TRA Taxpayer Education / Content Publication Responsible Officer | S26: Planned
A27: LRN-REQ04 | B27: 4 | C27: Learning & Content Management | D27: Categorize and Target Learning Content | E27: High | F27: The system shall allow authorized users to categorize learning content and define the member groups to which the content is applicable. | G27: 8 | H27: Mobile / Web / Admin | I27: Not started | J27: No implementation in prototype. | K27: Workflow, Audience, Cases/Numbering, Safeguarding, Scoped RBAC | L27: R2 | M27: S7–S9 | N27: M | O27: 5 | Q27: TC-LRN-REQ04-01..08 | R27: TRA Taxpayer Education / Learning Content Management Officer | S27: Planned
A28: LRN-REQ05 | B28: 4 | C28: Learning & Content Management | D28: Access and View Learning Content | E28: High | F28: The system shall allow an authenticated eligible member to access and view approved published learning content through the Mobile Application and Web Application. | G28: 8 | H28: Mobile / Web | I28: Partial | J28: Members list/view active content with own progress. Missing: targeting, browse by category, engagement analytics, resume, low-bandwidth media. | K28: Workflow, Audience, Cases/Numbering | L28: R2 | M28: S7–S9 | N28: L | O28: 6 | Q28: TC-LRN-REQ05-01..08 | R28: TRA Taxpayer Education / Tax Club Programme Responsible Officer | S28: Planned
A29: LRN-REQ06 | B29: 4 | C29: Learning & Content Management | D29: Learning Module Progress Tracking | E29: High | F29: The system shall record and maintain an eligible member’s progress through structured learning modules and display the member’s current learning status. | G29: 9 | H29: Mobile / Web / Admin | I29: Partial | J29: user_progress per content item (not_started/in_progress/completed). Missing: structured modules/lessons, mandatory components, resume position, version-aware history. | K29: Workflow, Audience, Audit | L29: R2 | M29: S7–S9 | N29: L | O29: 6 | Q29: TC-LRN-REQ06-01..09 | R29: TRA Taxpayer Education / Monitoring and Evaluation Responsible Officer | S29: Planned
A30: LRN-REQ07 | B30: 4 | C30: Learning & Content Management | D30: Search and Filter Learning Content | E30: Medium | F30: The system shall allow members to search and filter approved learning content through the Mobile Application and Web Application. | G30: 9 | H30: Mobile / Web / Admin | I30: Partial | J30: Title search and type filter. Missing: keywords/tags, category & level filters, relevance ordering, eligibility filtering. | K30: Workflow, Audience | L30: R2 | M30: S7–S9 | N30: M | O30: 4 | Q30: TC-LRN-REQ07-01..09 | R30: TRA Taxpayer Education / Content Management Responsible Officer | S30: Planned
A31: LRN-REQ08 | B31: 4 | C31: Learning & Content Management | D31: Content Versioning and Tax Information Updates | E31: High | F31: The system shall maintain controlled versions of learning content when approved information is revised and shall ensure that members are presented with the current published version. | G31: 9 | H31: Mobile / Web / Admin | I31: Not started | J31: No implementation in prototype. | K31: Workflow, Notifications, Audit, Safeguarding | L31: R2 | M31: S7–S9 | N31: L | O31: 8 | P31: D-10 | Q31: TC-LRN-REQ08-01..09 | R31: TRA Taxpayer Education / Relevant Tax Subject Matter Expert | S31: Planned
A32: COM-REQ01 | B32: 5 | C32: Questions, Expert Engagement & Community | D32: Submit Tax-Related Question | E32: High | F32: The system shall allow an authenticated Tax Club member to submit a tax-related question to TRA through the Mobile Application or Web Application. | G32: 9 | H32: Mobile / Web | I32: Not started | J32: No implementation in prototype. | K32: Workflow, Notifications, Cases/Numbering | L32: R4 | M32: S14–S17 | N32: M | O32: 5 | Q32: TC-COM-REQ01-01..09 | R32: TRA Taxpayer Education / Tax Subject Matter Expert | S32: Planned
A33: COM-REQ02 | B33: 5 | C33: Questions, Expert Engagement & Community | D33: Review, Categorize and Assign Submitted Questions | E33: High | F33: The system shall allow an authorized TRA officer to review, categorize and assign submitted member questions to an appropriate TRA subject matter expert for response. | G33: 8 | H33: Mobile / Web / Admin | I33: Not started | J33: No implementation in prototype. | K33: Workflow, Notifications, Audit, Cases/Numbering, Scoped RBAC | L33: R4 | M33: S14–S17 | N33: M | O33: 5 | Q33: TC-COM-REQ02-01..08 | R33: TRA Taxpayer Education Coordinator / Tax Subject Matter Expert | S33: Planned
A34: COM-REQ03 | B34: 5 | C34: Questions, Expert Engagement & Community | D34: TRA Expert Response to Member Questions | E34: High | F34: The system shall allow an assigned TRA subject matter expert to prepare and submit a response to a member question through the Administration Portal. | G34: 8 | H34: Mobile / Web / Admin | I34: Not started | J34: No implementation in prototype. | K34: Workflow, Notifications, Audit, Cases/Numbering, Scoped RBAC | L34: R4 | M34: S14–S17 | N34: M | O34: 5 | Q34: TC-COM-REQ03-01..08 | R34: TRA Tax Subject Matter Expert / Responsible Technical Department | S34: Planned
A35: COM-REQ04 | B35: 5 | C35: Questions, Expert Engagement & Community | D35: Review, Approve and Publish Questions and Answers | E35: High | F35: The system shall allow an authorized reviewer to review, approve, reject or return an expert response and publish approved questions and answers to the intended member or approved knowledge area. | G35: 8 | H35: Mobile / Web / Admin | I35: Not started | J35: No implementation in prototype. | K35: Workflow, Notifications, Audit, Cases/Numbering, Scoped RBAC | L35: R4 | M35: S14–S17 | N35: M | O35: 5 | P35: D-14 | Q35: TC-COM-REQ04-01..08 | R35: TRA Taxpayer Education Content Reviewer / Tax Subject Matter Expert | S35: Planned
A36: COM-REQ05 | B36: 5 | C36: Questions, Expert Engagement & Community | D36: Create and Manage Community Discussion Spaces | E36: High | F36: The system shall allow authorized users to create and manage moderated community discussion spaces for national, institutional, thematic, event, competition or other approved Tax Club engagement purposes. | G36: 8 | H36: Mobile / Web / Admin | I36: Not started | J36: No implementation in prototype. | K36: Workflow, Audience, Audit, Cases/Numbering, Safeguarding | L36: R4 | M36: S14–S17 | N36: L | O36: 8 | Q36: TC-COM-REQ05-01..08 | R36: TRA Tax Club Programme Coordinator / Community Moderator | S36: Planned
A37: COM-REQ06 | B37: 5 | C37: Questions, Expert Engagement & Community | D37: Create Community Posts, Comments and Replies | E37: High | F37: The system shall allow eligible Tax Club members to create posts, comments and replies within discussion spaces for which they have participation rights. | G37: 8 | H37: Mobile / Web | I37: Partial | J37: Global forum posts + replies; edit/soft-delete own. Missing: discussion spaces, content rules validation, mentions/notifications, participation restrictions. | K37: Workflow, Audience, Notifications, Audit, Safeguarding | L37: R4 | M37: S14–S17 | N37: L | O37: 6 | Q37: TC-COM-REQ06-01..08 | R37: TRA Community Moderator / Tax Club Programme Coordinator | S37: Planned
A38: COM-REQ07 | B38: 5 | C38: Questions, Expert Engagement & Community | D38: Report Inappropriate Content or User Behaviour | E38: High | F38: The system shall allow a user to report inappropriate community content or user behaviour for review by an authorized moderator. | G38: 8 | H38: Admin | I38: Not started | J38: No implementation in prototype. Built once with SAF-REQ01 (case engine). | K38: Workflow, Audit, Cases/Numbering, Safeguarding | L38: R4 | M38: S14–S17 | N38: S | O38: 2 | Q38: TC-COM-REQ07-01..08 | R38: TRA Community Moderator / Safeguarding Responsible Officer | S38: Planned
A39: COM-REQ08 | B39: 5 | C39: Questions, Expert Engagement & Community | D39: Moderate Community Content and User Participation | E39: High | F39: The system shall allow an authorized moderator to review reported or flagged community content and apply approved moderation actions to content or user participation. | G39: 8 | H39: Admin | I39: Partial | J39: Admin can soft-delete posts. Missing: moderation queue, actions (warn/hide/restrict/escalate), reasons, restore, history. Built once with SAF-REQ03. | K39: Workflow, Notifications, Audit, Cases/Numbering, Safeguarding | L39: R4 | M39: S14–S17 | N39: S | O39: 2 | Q39: TC-COM-REQ08-01..08 | R39: TRA Community Moderation Lead / ICT Security / Safeguarding Responsible Officer | S39: Planned
A40: COM-REQ09 | B40: 5 | C40: Questions, Expert Engagement & Community | D40: Inter-Institution Collaboration Groups | E40: Medium | F40: The system shall allow authorized users to create controlled collaboration groups that enable approved Tax Club members from different institutions to participate in joint learning, projects, campaigns or competitions. | G40: 8 | H40: Mobile / Web / Admin | I40: Not started | J40: No implementation in prototype. | K40: Workflow, Audience, Cases/Numbering, Safeguarding | L40: R4 | M40: S14–S17 | N40: M | O40: 5 | Q40: TC-COM-REQ09-01..08 | R40: TRA Tax Club Programme Coordinator / Community Moderator | S40: Planned
...

Sheet Foundations backlog
A1: Item | B1: Description | C1: Release | D1: Size | E1: Story points
A2: R0-01 | B2: Security remediation: rotate secrets, purge history, secret scanning | C2: R0 | D2: S | E2: 3
A3: R0-02 | B3: Monorepo + Docker Compose dev environment | C3: R0 | D3: M | E3: 5
A4: R0-03 | B4: CI/CD pipeline (lint, test, SAST, build, deploy to dev/staging) | C4: R0 | D4: L | E4: 8
A5: R0-04 | B5: Fix migrations (uuidMorphs, sessions), SQLite/MySQL test DB, factories | C5: R0 | D5: M | E5: 5
A6: R0-05 | B6: Feature-test harness + baseline tests for existing endpoints | C6: R0 | D6: M | E6: 5
A7: R0-06 | B7: OpenAPI generation + typed TS API client package | C7: R0 | D7: M | E7: 5
A8: R0-07 | B8: Audit Log service | C8: R0 | D8: M | E8: 5
A9: R0-08 | B9: Numbering/sequence service | C9: R0 | D9: S | E9: 3
A10: R0-09 | B10: Publishing Workflow engine + review queue API | C10: R0 | D10: L | E10: 8
A11: R0-10 | B11: Audience Rules engine | C11: R1 | D11: L | E11: 8
A12: R0-11 | B12: Scoped RBAC + Policies + role seeding | C12: R0 | D12: L | E12: 8
A13: R0-12 | B13: Media service (upload, scan, signed URLs, thumbnails) | C13: R1 | D13: M | E13: 5
... A21: RH-04 | B21: Platform administration (proposed M14): master data, settings, audit viewer | C21: R3 | D21: L | E21: 8

Sheet Release plan
A1: Release | B1: Name | C1: Sprints | D1: Start | E1: End | F1: Scope | G1: SRS reqs | H1: SRS points | I1: Foundation points | J1: Total points | K1: Capacity (pts) | L1: Load %
A2: R0 | B2: Stabilise & Foundations | C2: S0–S1 | D2: 46328 | E2: 46353 | F2: Security remediation, monorepo, CI/CD, Docker, migrations fixed, test harness, OpenAPI, shared services (Audit, Numbering, Workflow, Scoped RBAC), design system, Expo scaffold, i18n | G2: =COUNTIF(RTM!$L$2:$L$101,A2) | H2: =SUMIF(RTM!$L$2:$L$101,A2,RTM!$O$2:$O$101) | I2: =SUMIF('Foundations backlog'!$C$2:$C$100,A2,'Foundations backlog'!$E$2:$E$100) | J2: =H2+I2 | K2: 70 | L2: =J2/K2
A3: R1 | B3: Membership MVP (pilot) | C3: S2–S6 | D3: 46356 | E3: 46444 | F3: M1 Registration & accounts, M2 Profile & digital card, M3 Institutions & clubs, core Notifications (templates, transactional, inbox), Audience, Media and Case engines. Pilot with 10 institutions | G3: =COUNTIF(RTM!$L$2:$L$101,A3) | H3: =SUMIF(RTM!$L$2:$L$101,A3,RTM!$O$2:$O$101) | I3: =SUMIF('Foundations backlog'!$C$2:$C$100,A3,'Foundations backlog'!$E$2:$E$100) | J3: =H3+I3 | K3: 175 | L3: =J3/K3
A4: R2 | B4: Learn & Play — national launch | C4: S7–S9 | D4: 46447 | E4: 46486 | F4: M4 Learning, M8 Quiz & gamification, notification preferences. App Store / Play Store public launch | G4: =COUNTIF(RTM!$L$2:$L$101,A4) | H4: =SUMIF(RTM!$L$2:$L$101,A4,RTM!$O$2:$O$101) | I4: =SUMIF('Foundations backlog'!$C$2:$C$100,A4,'Foundations backlog'!$E$2:$E$100) | J4: =H4+I4 | K4: 105 | L4: =J4/K4
A5: R3 | B5: Engage | C5: S10–S13 | D5: 46489 | E5: 46542 | F5: M10 Events & campaigns, M7 Opportunities, Feedback, broadcasts, reminders, delivery tracking, platform administration (master data, settings, audit viewer) | G5: =COUNTIF(RTM!$L$2:$L$101,A5) | H5: =SUMIF(RTM!$L$2:$L$101,A5,RTM!$O$2:$O$101) | I5: =SUMIF('Foundations backlog'!$C$2:$C$100,A5,'Foundations backlog'!$E$2:$E$100) | J5: =H5+I5 | K5: 140 | L5: =J5/K5
A6: R4 | B6: Community, Safety & Competitions | C6: S14–S17 | D6: 46545 | E6: 46598 | F6: M12 Safety & moderation engine (first), M5 Q&A & community, M9 Competitions, rewards & certificates | G6: =COUNTIF(RTM!$L$2:$L$101,A6) | H6: =SUMIF(RTM!$L$2:$L$101,A6,RTM!$O$2:$O$101) | I6: =SUMIF('Foundations backlog'!$C$2:$C$100,A6,'Foundations backlog'!$E$2:$E$100) | J6: =H6+I6 | K6: 140 | L6: =J6/K6
A7: R5 | B7: Alumni, Mentorship & Reporting | C7: S18–S19 | D7: 46601 | E7: 46626 | F7: M6 Alumni & mentorship, reporting module (proposed M13), performance tuning | G7: =COUNTIF(RTM!$L$2:$L$101,A7) | H7: =SUMIF(RTM!$L$2:$L$101,A7,RTM!$O$2:$O$101) | I7: =SUMIF('Foundations backlog'!$C$2:$C$100,A7,'Foundations backlog'!$E$2:$E$100) | J7: =H7+I7 | K7: 70 | L7: =J7/K7
A8: RH | B8: Hardening, Pen-test, Final UAT, Go-live | C8: S20–S21 | D8: 46629 | E8: 46654 | F8: Independent penetration test, load test, regression, final UAT sign-off, data migration rehearsal, production go-live, then 4 weeks hypercare | G8: =COUNTIF(RTM!$L$2:$L$101,A8) | H8: =SUMIF(RTM!$L$2:$L$101,A8,RTM!$O$2:$O$101) | I8: =SUMIF('Foundations backlog'!$C$2:$C$100,A8,'Foundations backlog'!$E$2:$E$100) | J8: =H8+I8 | K8: 70 | L8: =J8/K8
A9: Total | G9: =SUM(G2:G8) | H9: =SUM(H2:H8) | I9: =SUM(I2:I8) | J9: =SUM(J2:J8) | K9: =SUM(K2:K8) | L9: =J9/K9
A11: Assumption: velocity 35 pts/sprint in every sprint for the recommended team in 07-execution-plan.md §4. Points include API, admin, member app and automated tests. Re-baseline after S3 using measured velocity.

Sheet Sprint calendar
A1: Sprint | B1: Start (Mon) | C1: End (Fri) | D1: Release | E1: Sprint review / demo
A2: S0 | B2: 46328 | C2: 46339 | D2: R0 | E2: Kick-off + architecture sign-off
A3: S1 | B3: 46342 | C3: 46353 | D3: R0 | E3: Demo to TRA product owner; UAT of previous release on staging
A4: S2 | B4: 46356 | C4: 46367 | D4: R1 | E4: Demo to TRA product owner; UAT of previous release on staging
A5: S3 | B5: 46391 | C5: 46402 | D5: R1 | E5: Demo to TRA product owner; UAT of previous release on staging
A6: S4 | B6: 46405 | C6: 46416 | D6: R1 | E6: Demo to TRA product owner; UAT of previous release on staging
A7: S5 | B7: 46419 | C7: 46430 | D7: R1 | E7: Demo to TRA product owner; UAT of previous release on staging
A8: S6 | B8: 46433 | C8: 46444 | D8: R1 | E8: Demo to TRA product owner; UAT of previous release on staging
A9: S7 | B9: 46447 | C9: 46458 | D9: R2 | E9: Demo to TRA product owner; UAT of previous release on staging
A10: S8 | B10: 46461 | C10: 46472 | D10: R2 | E10: Demo to TRA product owner; UAT of previous release on staging
A11: S9 | B11: 46475 | C11: 46486 | D11: R2 | E11: Demo to TRA product owner; UAT of previous release on staging
A12: S10 | B12: 46489 | C12: 46500 | D12: R3 | E12: Demo to TRA product owner; UAT of previous release on staging
A13: S11 | B13: 46503 | C13: 46514 | D13: R3 | E13: Demo to TRA product owner; UAT of previous release on staging
... A23: S21 | B23: 46643 | C23: 46654 | D23: RH | E23: Demo to TRA product owner; UAT of previous release on staging
A25: Buffer week 14-18 Dec 2026 (defects, tech debt, pilot prep) and holiday freeze 21-Dec-2026 to 03-Jan-2027 (no sprint). Hypercare runs 4 weeks after S21.

Sheet Legend
A1: Field | B1: Meaning
A2: Prototype status | B2: Partial = some behaviour exists in commit 7ad3d35 but key rules are missing; Not started = nothing usable
A3: Size | B3: S = 3 pts, M = 5, L = 8, XL = 13 (full stack: API + admin portal + member app + tests). Partial items discounted 25%
A4: Shared services | B4: Platform services from 02-solution-architecture.md §4 that the requirement depends on (auto-derived from SRS text; verify in refinement)
A5: Decision refs | B5: Open business decisions in 09-decisions-and-business-rules-register.md that block final acceptance criteria
A6: Test cases | B6: One test case per related sub-requirement, numbered TC-<ReqID>-NN; UAT scripts derived from SRS Behavior + Exceptional rows
A7: Delivery status | B7: Maintained by the delivery team each sprint (drop-down)
